Internal Server Error: /oauth_response/
Traceback (most recent call last):
  File "/usr/local/lib/python2.7/site-packages/django/core/handlers/base.py", line 132, in get_response
    response = wrapped_callback(request, *callback_args, **callback_kwargs)
  File "/code/getschema/views.py", line 120, in oauth_response
    schema.save()
  File "/usr/local/lib/python2.7/site-packages/django/db/models/base.py", line 710, in save
    force_update=force_update, update_fields=update_fields)
  File "/usr/local/lib/python2.7/site-packages/django/db/models/base.py", line 738, in save_base
    updated = self._save_table(raw, cls, force_insert, force_update, using, update_fields)
  File "/usr/local/lib/python2.7/site-packages/django/db/models/base.py", line 822, in _save_table
    result = self._do_insert(cls._base_manager, using, fields, update_pk, raw)
  File "/usr/local/lib/python2.7/site-packages/django/db/models/base.py", line 861, in _do_insert
    using=using, raw=raw)
  File "/usr/local/lib/python2.7/site-packages/django/db/models/manager.py", line 127, in manager_method
    return getattr(self.get_queryset(), name)(*args, **kwargs)
  File "/usr/local/lib/python2.7/site-packages/django/db/models/query.py", line 920, in _insert
    return query.get_compiler(using=using).execute_sql(return_id)
  File "/usr/local/lib/python2.7/site-packages/django/db/models/sql/compiler.py", line 963, in execute_sql
    cursor.execute(sql, params)
  File "/usr/local/lib/python2.7/site-packages/django/db/backends/utils.py", line 79, in execute
    return super(CursorDebugWrapper, self).execute(sql, params)
  File "/usr/local/lib/python2.7/site-packages/django/db/backends/utils.py", line 64, in execute
    return self.cursor.execute(sql, params)
  File "/usr/local/lib/python2.7/site-packages/django/db/utils.py", line 97, in __exit__
    six.reraise(dj_exc_type, dj_exc_value, traceback)
  File "/usr/local/lib/python2.7/site-packages/django/db/backends/utils.py", line 64, in execute
    return self.cursor.execute(sql, params)
ProgrammingError: relation "getschema_schema" does not exist
LINE 1: INSERT INTO "getschema_schema" ("random_id", "created_date",...
                    ^

Internal Server Error: /loading/c80c59f0-1281-4148-98f7-a194d5a4b541/
Traceback (most recent call last):
  File "/usr/local/lib/python2.7/site-packages/django/core/handlers/base.py", line 132, in get_response
    response = wrapped_callback(request, *callback_args, **callback_kwargs)
  File "/code/getschema/views.py", line 154, in loading
    schema = get_object_or_404(Schema, random_id = schema_id)
  File "/usr/local/lib/python2.7/site-packages/django/shortcuts.py", line 155, in get_object_or_404
    return queryset.get(*args, **kwargs)
  File "/usr/local/lib/python2.7/site-packages/django/db/models/query.py", line 338, in get
    (self.model._meta.object_name, num)
MultipleObjectsReturned: get() returned more than one Schema -- it returned 2!
